Workbook

Sheet Kostenübersicht
A1: Sofortangebot — Laufende Geschäftskosten
A2: Stand: 2026-09-02 · Head of Finance · Bestandsaufnahme CoS-F-001 · Beleg-Details je Rechnung stehen im Blatt 'Rechnungsjournal' · orange = auffällig, bitte klären · grau = noch kein Beleg · Umsatzsteuer-Status aktualisiert 17.09.2026: Regelbesteuerung (Verzicht nach § 19 Abs. 2 UStG), Details in docs/preismodell.md.
A4: Dienst | B4: Kategorie | C4: Währung | D4: Monatsbetrag (aktuellster Beleg, brutto) | E4: Abrechnungsrhythmus | F4: Vertragsstand / Kündigungsfrist | G4: USt-Behandlung | H4: Status | I4: Quelle / Notiz
A5: Supabase | B5: Hosting / Datenbank | C5: USD | D5: 53.83 | E5: monatlich: Pro Plan $25 Grundgebühr + nutzungsbasierte Zusatzkosten (Compute, Realtime, Egress, Functions, …) | F5: 2 Projekte laut Doku vorgesehen (Staging + Produktion 'yqlledouhfovytifeekd') | G5: Reverse Charge (§ 13b UStG, Singapur-Anbieter). AKTUALISIERT 17.09.2026: Mit der Regelbesteuerung (Verzicht nach § 19 Abs. 2 UStG, Entscheidung Sandy vom 17.09.2026) ist die Steuer durchlaufend — angemeldet und im selben Zug als Vorsteuer gezogen, Saldo null. Der Monatsbetrag in Spalte D ist damit der volle Kostenwert. | H5: auffällig — Betrag bestätigt, Trend + Projektanzahl bitte klären | I5: 4 Belege (Journal 2026-003/006/008/016): 23.05. $25,00 / 23.06. $49,97 / 23.07. $54,30 / 23.08. $53,83 — nach dem Anstieg jetzt erstmals leicht rückläufig. Rechnungen zeigten bis Juli 5 Projekt-Referenzen, dokumentiert sind nur 2; im August-Beleg taucht eine davon erstmals nicht mehr auf (jetzt 4). Bitte weiter beobachten/klären, ob alle nötig sind.
A6: Vercel | B6: Hosting / Deployment | C6: USD | D6: 23.8 | E6: monatlich: Pro Plan $20 + 19% USt, seit Juni zusätzlich 'Observability Plus' Position mit $0,00 | F6: Kündigungsfrist unbekannt | G6: USt. direkt ausgewiesen (EU VAT EU056329113), kein Reverse Charge | H6: bestätigt | I6: 4 Belege (Journal 2026-002/005/007/015): 22.05., 22.06., 22.07., 22.08. — durchgängig $23,80, stabil. Zahlungsart jetzt bestätigt: Kreditkarte Visa •••3991.
A7: Anthropic — direkt | B7: KI / API | C7: USD | D7: 53.55 | E7: unklar — Beleg trägt 'Prepaid extra usage, Individual plan', evtl. einmaliger Nachkauf statt Fixbetrag | F7: unbekannt | G7: USt. direkt ausgewiesen (EU VAT IE4276970QH), kein Reverse Charge | H7: auffällig — bitte klären ob wiederkehrend | I7: 1 Beleg (Journal 2026-010) vom 17.08.2026 über $45,00 + USt = $53,55, Geschäftsadresse Wielandstraße 11, mit hinterlegter deutscher Steuernummer.
A8: Claude Pro (Apple/iTunes) | B8: KI / Software | C8: EUR | D8: 22 | E8: monatlich, automatische Verlängerung, Zahlung per PayPal | F8: monatlich kündbar (Apple-Abo) | G8: USt. direkt von Apple ausgewiesen, kein Reverse Charge | H8: auffällig — geschäftlich/privat + fehlende Monate klären | I8: 2 Belege (Journal 2026-001/009): 04.05. und 03.08., je 22,00 € — Juni/Juli-Belege fehlen noch. Separates Abo zur direkten Anthropic-Rechnung, andere Rechnungsadresse (Krampasplatz 4b). Bitte klären: zweite geschäftliche Claude-Lizenz oder privates Abo?
A9: OpenAI | B9: KI / API | C9: USD | D9: 17.85 | E9: nutzungsbasiert, Beleg zeigt eine Guthaben-Aufladung ('usage credit'), kein fester Monatsbetrag erkennbar | F9: unbekannt | G9: USt. direkt ausgewiesen (EU OSS VAT EU372041333), kein Reverse Charge | H9: bestätigt | I9: 1 Beleg (Journal 2026-004) vom 14.06.2026 über $15,00 + USt = $17,85. Rechnungsempfänger 'Hugo' / runningwithhugo@outlook.de — ist Sandys eigener Account, Name/E-Mail-Alias lässt sich bei OpenAI nachträglich nicht mehr ändern (geklärt 19.08.2026).
A10: Resend | B10: E-Mail | C10: ? | E10: unbekannt | F10: unbekannt | G10: unbekannt | H10: kein Beleg gefunden | I10: Im Code bestätigt (Paket 'resend', RESEND_API_KEY), aber noch keine Rechnung im Belege-Ordner.
A11: Domain sofortangebot.app | B11: Domain | C11: EUR | D11: 2.5 | E11: 'IONOS Mail Basic 5' (Postfach) laufend 2,50 €/Monat. Domain .app + 'Domain Guard' (Privatsphärenschutz) jährlich, zusammen 13,00 € brutto — nächste Fälligkeit ~06/2027. | F11: Vertragsnummer 111811442 bei IONOS SE — Achtung: bündelt auf denselben Rechnungen auch mehrere fremde Domains, siehe Journal | G11: USt. direkt von IONOS ausgewiesen (USt-IdNr. DE815563912), kein Reverse Charge | H11: bestätigt | I11: 5 Belege (Journal 2026-011 bis 2026-015/017 — Rechnungsnummern siehe dort) unter einer gebündelten IONOS-Rechnung. Domain sofortangebot.app wurde 08.06.2026 registriert. Sandy hat am 02.09.2026 bestätigt, dass 'Domain Guard' und 'IONOS Mail Basic 5' ebenfalls zu sofortangebot.app gehören. Fremde Domains ('einfach-anfrage.com', 'einfachanfrage-hochzeitsfotografie.de' u. a.) laufen über denselben IONOS-Vertrag, aber NICHT mitgezählt.
A12: Sentry | B12: Monitoring / Error-Tracking | C12: ? | E12: unbekannt | F12: unbekannt | G12: unbekannt | H12: kein Beleg gefunden | I12: Im Code gefunden ('@sentry/nextjs'), nicht in Sandys Ausgangsliste, noch keine Rechnung im Ordner.
A13: Stripe | B13: Zahlungsabwicklung | C13: ? | E13: transaktionsbasiert (keine feste Monatsgebühr erwartet) | F13: unbekannt | G13: unbekannt | H13: kein Beleg erwartet | I13: Im Code bestätigt ('stripe' Paket). Gebühren pro Transaktion statt Fixkosten — relevant erst mit Umsatz-Tracking in Phase 2.
A14: GitHub Actions (Backup-Artefakte) | B14: CI / Infra | C14: ? | E14: nutzungsbasiert (Speicher/Minuten) | F14: abhängig vom GitHub-Plan | G14: unbekannt | H14: zu prüfen | I14: Tägliches DB-Backup speichert Artefakte 30/90/365 Tage. Kann bei privatem Repo über das Freikontingent hinaus Kosten verursachen — noch kein Beleg.
A16: DIN Media — VOB Gesamtausgabe 2019 (E-Book) | B16: Fachliteratur — einmalig | C16: EUR einmalig | E16: einmalig, 54,00 € brutto am 04.09.2026 (Beleg 2026-018) | F16: kein Vertrag, Einmalkauf | G16: USt. 7 % ermaessigt (E-Book), von DIN Media ausgewiesen | H16: bestätigt — kein laufender Posten, steht deshalb ohne Monatsbetrag und faellt nicht in die Monatssummen
A18: Summe USD-Positionen (siehe Status-Spalte für Vorbehalte) | D18: =SUMIF(C5:C16,"USD",D5:D16)
A19: Summe EUR-Positionen (siehe Status-Spalte für Vorbehalte) | D19: =SUMIF(C5:C16,"EUR",D5:D16)
A20: Summe gesamt in EUR (USD-Positionen zum BMF-Kurs August 2026) | D20: =D19+D18/Rechnungsjournal!$B$42
A21: Hinweis: USD- und EUR-Positionen werden weiterhin getrennt summiert, weil die Belege in unterschiedlichen Währungen vorliegen. Die Gesamtsumme in EUR rechnet die USD-Positionen mit dem amtlichen BMF-Umsatzsteuer-Umrechnungskurs des jeweils letzten Monats um (§ 16 Abs. 6 UStG) — die Kurse stehen im Blatt 'Rechnungsjournal' unter der Journaltabelle. Beleg-Details je Rechnung (Rechnungsnummer, Netto/USt/Brutto, Beleg-Datei) stehen ebenfalls im Blatt 'Rechnungsjournal'.

Sheet Rechnungsjournal
A1: Rechnungsjournal — Belege im Detail (für Buchhaltung / Steuerberater)
A2: Ein Beleg = eine Zeile, chronologisch. Enthält alles, was ein Steuerberater für die Verbuchung braucht: Rechnungsnummer, Leistungszeitraum, Netto/USt/Brutto, steuerliche Einordnung (Reverse Charge ja/nein), Zahlungsart und die Original-Beleg-Datei im Rechnungen-Ordner. Bitte Zeilen hier nie überschreiben, nur neue anhängen (Nachvollziehbarkeit).
A4: Beleg-Nr. | B4: Rechnungsdatum | C4: Rechnungsnr. (Anbieter) | D4: Leistungszeitraum | E4: Anbieter | F4: Anbieter-Land | G4: Dienst | H4: Rechnungsempfänger lt. Beleg | I4: Währung | J4: Netto-Betrag | K4: USt-Satz | L4: USt-Betrag | M4: Brutto-Betrag | N4: Sofortangebot-Anteil (Brutto) | O4: Steuerliche Einordnung | P4: Betrag EUR (Brutto, ca.) | Q4: Zahlungsart | R4: Beleg-Datei (Ordner 'Rechnungen') | S4: Auffälligkeit / Notiz | T4: Vorsteuer EUR (erst ab Regelbesteuerung, F-006 = B)
A5: 2026-001 | B5: 46146 | C5: MVS2VFHBYG / Dok. 846129332588 | D5: 04.05.–03.06.2026 (Abo-Monat) | E5: Apple Distribution International Ltd. (Vertrieb für Claude Pro) | F5: Irland | G5: Claude Pro (Apple/iTunes) | H5: Sandra Holm, Krampasplatz 4b, 14199 Berlin | I5: EUR | J5: 18.49 | K5: 0.19 | L5: 3.51 | M5: 22 | N5: 22 | O5: USt. (19%) direkt von Apple ausgewiesen, kein Reverse Charge. | P5: =M5 | Q5: PayPal | R5: Deine Rechnung von Apple.eml | S5: Abo verlängert sich automatisch monatlich. Rechnungsadresse weicht von den übrigen Belegen ab (Krampasplatz 4b statt Wielandstraße 11) — bitte klären, welche Adresse aktuell/richtig ist. | T5: =ROUND(L5,2)
A6: 2026-002 | B6: 46164 | C6: TT0BDQ8S-0001 | D6: 22.05.–21.06.2026 | E6: Vercel Inc. | F6: USA | G6: Vercel | H6: einfachanfrage's projects, Wielandstraße 11, 12159 Berlin (einfachanfrage@outlook.com) | I6: USD | J6: 20 | K6: 0.19 | L6: 3.8 | M6: 23.8 | N6: 23.8 | O6: USt. (19%) direkt von Vercel ausgewiesen (EU VAT EU056329113), kein Reverse Charge. | P6: =M6/$B$39 | Q6: Kreditkarte Visa •••3991 | R6: Invoice-TT0BDQ8S-0001.pdf / Receipt-2392-5328.pdf | S6: Zahlungsart nachträglich ergänzt (Update 2026-09-02) anhand Zahlungsbeleg Receipt-2392-5328.pdf. | T6: =ROUND(L6/$B$39,2)
A7: 2026-003 | B7: 46165 | C7: MVGOOM-00003 | D7: 23.05.–22.06.2026 | E7: Supabase Pte. Ltd. | F7: Singapur | G7: Supabase | H7: Sandra Holm, Wielandstraße 11, Berlin (einfachanfrage@outlook.com) | I7: USD | J7: 25 | K7: Reverse Charge | L7: 0 | M7: 25 | N7: 25 | O7: Reverse Charge — Supabase weist keine USt aus. Sandy startet als Kleinunternehmerin nach §19 UStG (bestätigt 19.08.2026), Gewerbe aber noch nicht angemeldet. Nach Kleinunternehmerregelung i. d. R. keine Vorsteuer ziehbar, aber die USt-Pflicht auf reverse-charge-Leistungen aus dem Ausland (§13b UStG) kann trotzdem bestehen bleiben — das ist keine verbindliche Auskunft von mir, bitte mit Steuerberater final klären, sobald einer feststeht. | P7: =M7/$B$39 | Q7: unbekannt | R7: Invoice-MVGOOM-00003.pdf | S7: Nur Pro-Plan-Grundgebühr, keine Nutzungsgebühren in diesem Monat. | T7: 0,00 (durchlaufend)
A8: 2026-004 | B8: 46187 | C8: YL9K6L19-0001 | D8: — | E8: OpenAI OpCo, LLC | F8: USA | G8: OpenAI | H8: Hugo, Wielandstraße 11, 12159 Berlin (runningwithhugo@outlook.de) | I8: USD | J8: 15 | K8: 0.19 | L8: 2.85 | M8: 17.85 | N8: 17.85 | O8: USt. (19%) direkt von OpenAI ausgewiesen (EU OSS VAT EU372041333), kein Reverse Charge. | P8: =M8/$B$40 | Q8: unbekannt | R8: Invoice-YL9K6L19-0001.pdf | S8: Geklärt (19.08.2026): Konto gehört Sandy, 'Hugo' ist ein historischer Nutzername/E-Mail-Alias bei OpenAI, der sich im Nachhinein nicht mehr auf 'Sandra Holm' ändern lässt. Kein falscher Account — nur zur Info für den Steuerberater vermerkt, falls Name/E-Mail auf dem Beleg auffallen. | T8: =ROUND(L8/$B$40,2)
A9: 2026-005 | B9: 46195 | C9: TT0BDQ8S-0003 | D9: 22.06.–21.07.2026 | E9: Vercel Inc. | F9: USA | G9: Vercel | H9: einfachanfrage's projects, Wielandstraße 11, 12159 Berlin (einfachanfrage@outlook.com) | I9: USD | J9: 20 | K9: 0.19 | L9: 3.8 | M9: 23.8 | N9: 23.8 | O9: USt. (19%) direkt von Vercel ausgewiesen (EU VAT EU056329113), kein Reverse Charge. | P9: =M9/$B$40 | Q9: Kreditkarte Visa •••3991 | R9: Invoice-TT0BDQ8S-0003.pdf / Receipt-2268-5813.pdf | S9: Zusätzliche Position 'Observability Plus' mit $0,00 seit diesem Monat. Zahlungsart nachträglich ergänzt (Update 2026-09-02) anhand Zahlungsbeleg Receipt-2268-5813.pdf. | T9: =ROUND(L9/$B$40,2)
A10: 2026-006 | B10: 46196 | C10: MVGOOM-00005 | D10: 23.05.–22.06.2026 (Nutzung) + 23.06.–22.07.2026 (Pro Plan) | E10: Supabase Pte. Ltd. | F10: Singapur | G10: Supabase | H10: Sandra Holm, Wielandstraße 11, Berlin (einfachanfrage@outlook.com) | I10: USD | J10: 49.97 | K10: Reverse Charge | L10: 0 | M10: 49.97 | N10: 49.97 | O10: Reverse Charge — Supabase weist keine USt aus. Sandy startet als Kleinunternehmerin nach §19 UStG (bestätigt 19.08.2026), Gewerbe aber noch nicht angemeldet. Nach Kleinunternehmerregelung i. d. R. keine Vorsteuer ziehbar, aber die USt-Pflicht auf reverse-charge-Leistungen aus dem Ausland (§13b UStG) kann trotzdem bestehen bleiben — das ist keine verbindliche Auskunft von mir, bitte mit Steuerberater final klären, sobald einer feststeht. | P10: =M10/$B$40 | Q10: unbekannt | R10: Invoice-MVGOOM-00005.pdf / Receipt-MVGOOM-00005.pdf | S10: Erstmals nennenswerte Nutzungsgebühren (Compute Hours) zusätzlich zur Pro-Plan-Grundgebühr. Zahlungsbeleg (Receipt-MVGOOM-00005.pdf) nachträglich ergänzt (Update 2026-09-02), keine neue Zeile — identischer Betrag/Zeitraum wie diese Rechnung. | T10: 0,00 (durchlaufend)
A11: 2026-007 | B11: 46225 | C11: TT0BDQ8S-0004 | D11: 22.07.–21.08.2026 | E11: Vercel Inc. | F11: USA | G11: Vercel | H11: einfachanfrage's projects, Wielandstraße 11, 12159 Berlin (einfachanfrage@outlook.com) | I11: USD | J11: 20 | K11: 0.19 | L11: 3.8 | M11: 23.8 | N11: 23.8 | O11: USt. (19%) direkt von Vercel ausgewiesen (EU VAT EU056329113), kein Reverse Charge. | P11: =M11/$B$41 | Q11: Kreditkarte Visa •••3991 | R11: Invoice-TT0BDQ8S-0004.pdf / Receipt-2842-3830.pdf | S11: Zahlungsart nachträglich ergänzt (Update 2026-09-02) anhand Zahlungsbeleg Receipt-2842-3830.pdf. | T11: =ROUND(L11/$B$41,2)
A12: 2026-008 | B12: 46226 | C12: MVGOOM-00006 | D12: 23.06.–22.07.2026 (Nutzung) + 23.07.–22.08.2026 (Pro Plan) | E12: Supabase Pte. Ltd. | F12: Singapur | G12: Supabase | H12: Sandra Holm, Wielandstraße 11, Berlin (einfachanfrage@outlook.com) | I12: USD | J12: 54.3 | K12: Reverse Charge | L12: 0 | M12: 54.3 | N12: 54.3 | O12: Reverse Charge — Supabase weist keine USt aus. Sandy startet als Kleinunternehmerin nach §19 UStG (bestätigt 19.08.2026), Gewerbe aber noch nicht angemeldet. Nach Kleinunternehmerregelung i. d. R. keine Vorsteuer ziehbar, aber die USt-Pflicht auf reverse-charge-Leistungen aus dem Ausland (§13b UStG) kann trotzdem bestehen bleiben — das ist keine verbindliche Auskunft von mir, bitte mit Steuerberater final klären, sobald einer feststeht. | P12: =M12/$B$41 | Q12: unbekannt | R12: Invoice-MVGOOM-00006.pdf / Receipt-MVGOOM-00006.pdf | S12: Nutzungsgebühren weiter gestiegen, neu: 'Realtime Peak Connections' $10,00. Rechnung listet 5 verschiedene Projekt-Referenzen, dokumentiert sind nur 2 (Staging + Produktion). Zahlungsbeleg (Receipt-MVGOOM-00006.pdf) nachträglich ergänzt (Update 2026-09-02), keine neue Zeile. | T12: 0,00 (durchlaufend)
A13: 2026-009 | B13: 46237 | C13: MVS3312KT5 / Dok. 674170779929 | D13: 03.08.–02.09.2026 (Abo-Monat) | E13: Apple Distribution International Ltd. (Vertrieb für Claude Pro) | F13: Irland | G13: Claude Pro (Apple/iTunes) | H13: Sandra Holm, Krampasplatz 4b, 14199 Berlin | I13: EUR | J13: 18.49 | K13: 0.19 | L13: 3.51 | M13: 22 | N13: 22 | O13: USt. (19%) direkt von Apple ausgewiesen, kein Reverse Charge. | P13: =M13 | Q13: PayPal | R13: Deine Käufe bei Apple.eml | S13: Belege für die Juni- und Juli-Abbuchung dieses Abos fehlen noch (vermutlich auch je ~22 €) — bitte in Apple-Kaufhistorie/Postfach nachsehen und ergänzen. | T13: =ROUND(L13,2)
A14: 2026-010 | B14: 46251 | C14: CBBICKXQ-0001 | D14: — | E14: Anthropic, PBC | F14: USA | G14: Anthropic — direkt | H14: Sandra Holm, Wielandstraße 11, 12159 Berlin, DE STN 89365407818 | I14: USD | J14: 45 | K14: 0.19 | L14: 8.55 | M14: 53.55 | N14: 53.55 | O14: USt. (19%) direkt von Anthropic ausgewiesen (EU VAT IE4276970QH), kein Reverse Charge. | P14: =M14/$B$42 | Q14: unbekannt (Online-Zahlung) | R14: Invoice-CBBICKXQ-0001.pdf | S14: Rechnung nennt eine deutsche Steuernummer (DE STN 89365407818) — da laut Sandy noch kein Gewerbe angemeldet ist (Stand 19.08.2026), vermutlich Sandys private Steuer-ID, nicht zwingend eine Geschäfts-Steuernummer. Position heißt 'Prepaid extra usage, Individual plan' — bitte klären: wiederkehrender Posten oder einmaliger Nachkauf von Nutzungsvolumen? | T14: =ROUND(L14/$B$42,2)
A15: 2026-011 | B15: 46138 | C15: 100185593347 | D15: Abrechnung 26.04.2026 (Vertragszeitraum Domain: 25.04.2026–24.04.2027) | E15: IONOS SE | F15: Deutschland | G15: Domain sofortangebot.app | H15: Sandra Holm, Wielandstr. 11, 12159 Berlin | I15: EUR | J15: 0.81 | K15: 0.19 | L15: 0.15 | M15: 0.96 | N15: 0 | O15: USt. (19%) direkt von IONOS ausgewiesen (deutscher Anbieter, USt-IdNr. DE815563912), kein Reverse Charge. | P15: =M15 | Q15: PayPal | R15: IONOS Rechnung 2026-04-26 - RG_100185593347.pdf | S15: Rechnung betrifft ausschließlich die Domain 'einfach-anfrage.com' (Position 1) — das ist NICHT sofortangebot.app, sondern offensichtlich ein anderes/älteres Projekt. Deshalb Sofortangebot-Anteil = 0,00 €. Alle 5 IONOS-Rechnungen (April–August 2026) laufen unter derselben Vertragsnummer 111811442, die mehrere Domains bündelt — bitte im Blick behalten, dass hier nicht versehentlich fremde Projektkosten mitgezählt werden. Neu entdeckt und nachgetragen: Update 2026-09-02. | T15: =ROUND(L15,2)
A16: 2026-012 | B16: 46168 | C16: 100187536255 | D16: Abrechnung 26.05.2026 (Vertragszeiträume: 11.05.2026–10.05.2027 bzw. 22.05.2026–21.05.2027) | E16: IONOS SE | F16: Deutschland | G16: Domain sofortangebot.app | H16: Sandra Holm, Wielandstr. 11, 12159 Berlin | I16: EUR | J16: 27.73 | K16: 0.19 | L16: 5.27 | M16: 33 | N16: 0 | O16: USt. (19%) direkt von IONOS ausgewiesen (deutscher Anbieter, USt-IdNr. DE815563912), kein Reverse Charge. | P16: =M16 | Q16: PayPal | R16: IONOS Rechnung 2026-05-26 - RG_100187536255.pdf | S16: Rechnung betrifft drei fremde Domains ('einfachanfrage.com', 'einfachanfrage-hochzeitsfotografie.de', 'einfachanfrage-tattoo.de') plus deren Registrierungsgebühren — keine davon ist sofortangebot.app. Deshalb Sofortangebot-Anteil = 0,00 €. Neu entdeckt und nachgetragen: Update 2026-09-02. | T16: =ROUND(L16,2)
A17: 2026-013 | B17: 46199 | C17: 100189466040 | D17: Abrechnung 26.06.2026 (Domain .app + Domain Guard: 08.06.2026–07.06.2027; IONOS Mail Basic 5: 08.06.–07.07.2026) | E17: IONOS SE | F17: Deutschland | G17: Domain sofortangebot.app | H17: Sandra Holm, Wielandstr. 11, 12159 Berlin | I17: EUR | J17: 13.03 | K17: 0.19 | L17: 2.47 | M17: 15.5 | N17: 15.5 | O17: USt. (19%) direkt von IONOS ausgewiesen, kein Reverse Charge. Hinweis für Steuerberater: Die Spalte 'Betrag (EUR)' auf IONOS-Rechnungen zeigt Brutto-Positionsbeträge, obwohl daneben eine MwSt.-Spalte steht — Netto/USt werden nur für die Rechnungssumme insgesamt ausgewiesen, nicht je Zeile. Der Sofortangebot-Anteil (Brutto) wurde deshalb direkt aus den Positionsbeträgen gebildet. | P17: =M17 | Q17: PayPal | R17: IONOS Rechnung 2026-06-26 - RG_100189466040.pdf | S17: Erste Rechnung mit sofortangebot.app: Domain .app registriert 08.06.2026 (12,00 € brutto). Sandy hat am 02.09.2026 bestätigt, dass 'Domain Guard' (1,00 € brutto, Privatsphärenschutz) UND 'IONOS Mail Basic 5' (2,50 €/Monat, ab 08.06.2026) ebenfalls zu sofortangebot.app gehören — damit ist die komplette Rechnung (15,50 €) dem Sofortangebot-Anteil zugeordnet. Alle 5 IONOS-Rechnungen laufen unter Vertragsnummer 111811442, die mehrere fremde Domains bündelt (siehe 2026-011/012), die weiterhin ausgeschlossen bleiben. Neu entdeckt: Update 2026-09-02, Zuordnung bestätigt 2026-09-02. | T17: =ROUND(L17,2)
A18: 2026-014 | B18: 46229 | C18: 100191208015 | D18: 08.07.–07.08.2026 (IONOS Mail Basic 5) | E18: IONOS SE | F18: Deutschland | G18: Domain sofortangebot.app | H18: Sandra Holm, Wielandstr. 11, 12159 Berlin | I18: EUR | J18: 2.1 | K18: 0.19 | L18: 0.4 | M18: 2.5 | N18: 2.5 | O18: USt. (19%) direkt von IONOS ausgewiesen, kein Reverse Charge. | P18: =M18 | Q18: PayPal | R18: IONOS Rechnung 2026-07-26 - RG_100191208015.pdf | S18: Nur Position 'IONOS Mail Basic 5' (2,50 €) — dasselbe Postfach wie in 2026-013. Sandy hat am 02.09.2026 bestätigt, dass es zu sofortangebot.app gehört. Neu entdeckt: Update 2026-09-02, Zuordnung bestätigt 2026-09-02. | T18: =ROUND(L18,2)
A19: 2026-015 | B19: 46256 | C19: TT0BDQ8S-0005 | D19: 22.08.–21.09.2026 | E19: Vercel Inc. | F19: USA | G19: Vercel | H19: einfachanfrage's projects, Wielandstraße 11, 12159 Berlin (einfachanfrage@outlook.com) | I19: USD | J19: 20 | K19: 0.19 | L19: 3.8 | M19: 23.8 | N19: 23.8 | O19: USt. (19%) direkt von Vercel ausgewiesen (EU VAT EU056329113), kein Reverse Charge. | P19: =M19/$B$42 | Q19: Kreditkarte Visa •••3991 | R19: Invoice-TT0BDQ8S-0005.pdf / Receipt-2017-0960.pdf | S19: Weiterhin 'Observability Plus' Position mit $0,00. Zahlungsart über Zahlungsbeleg bestätigt: Visa-Karte endet auf 3991 (gilt rückwirkend auch für 2026-002/005/007, dort ergänzt). | T19: =ROUND(L19/$B$42,2)
A20: 2026-016 | B20: 46257 | C20: MVGOOM-00007 | D20: 23.07.–22.08.2026 (Nutzung) + 23.08.–22.09.2026 (Pro Plan) | E20: Supabase Pte. Ltd. | F20: Singapur | G20: Supabase | H20: Sandra Holm, Wielandstraße 11, Berlin (einfachanfrage@outlook.com) | I20: USD | J20: 53.83 | K20: Reverse Charge | L20: 0 | M20: 53.83 | N20: 53.83 | O20: Reverse Charge — Supabase weist keine USt aus. Sandy startet als Kleinunternehmerin nach §19 UStG (bestätigt 19.08.2026), Gewerbe aber noch nicht angemeldet. Nach Kleinunternehmerregelung i. d. R. keine Vorsteuer ziehbar, aber die USt-Pflicht auf reverse-charge-Leistungen aus dem Ausland (§13b UStG) kann trotzdem bestehen bleiben — das ist keine verbindliche Auskunft von mir, bitte mit Steuerberater final klären, sobald einer feststeht. | P20: =M20/$B$42 | Q20: unbekannt | R20: Invoice-MVGOOM-00007.pdf / Receipt-MVGOOM-00007.pdf | S20: Nutzungsgebühren leicht gesunken ggü. Juli ($54,30 → $53,83). Positiv aufgefallen: nur noch 4 Projekt-Referenzen in den Positionen sichtbar (bkldyddstovvkkhpiqiy, ezgyklsigzaowrrpqtpv, qsdbnckgzllyypmkmzhc, yqlledouhfovytifeekd) — die fünfte aus den Vormonaten ('ytvysmwepajatcdhkgup') taucht hier nicht mehr auf. Könnte bedeuten, dass ein ungenutztes Projekt zwischenzeitlich entfernt wurde (siehe offener Punkt '5 vs. 2 dokumentierte Projekte'). | T20: 0,00 (durchlaufend)
A21: 2026-017 | B21: 46260 | C21: 100192688572 | D21: 08.08.–07.09.2026 (IONOS Mail Basic 5) | E21: IONOS SE | F21: Deutschland | G21: Domain sofortangebot.app | H21: Sandra Holm, Wielandstr. 11, 12159 Berlin | I21: EUR | J21: 2.1 | K21: 0.19 | L21: 0.4 | M21: 2.5 | N21: 2.5 | O21: USt. (19%) direkt von IONOS ausgewiesen, kein Reverse Charge. | P21: =M21 | Q21: PayPal | R21: IONOS Rechnung 2026-08-26 - RG_100192688572.pdf | S21: Wie Juli: nur 'IONOS Mail Basic 5' (2,50 €). Sandy hat am 02.09.2026 bestätigt, dass es zu sofortangebot.app gehört (siehe 2026-013/014). | T21: =ROUND(L21,2)
A22: 2026-018 | B22: 46269 | C22: B6818653 | D22: Leistung/Lieferung 04.09.2026 (Download), Bestellung 02.09.2026 | E22: DIN Media GmbH | F22: Deutschland | G22: Fachliteratur — VOB Gesamtausgabe 2019, Teil A/B/C (E-Book) | H22: Sandra Holm, Wielandstr. 11, 12159 Berlin | I22: EUR | J22: 50.47 | K22: 0.07 | L22: 3.53 | M22: 54 | N22: 54 | O22: USt. (7 % ermaessigt, § 12 Abs. 2 Nr. 14 UStG — E-Book) direkt von DIN Media ausgewiesen, USt-IdNr. DE811236989. Inlandsrechnung, kein Reverse Charge. | P22: =M22 | Q22: Vorkasse, bezahlt 03.09.2026 (Auftrag 11964539), Rechnung weist 54,00 EUR als bereits gezahlt aus | R22: 406270316_ZUGFeRD.pdf | S22: ERSTE ECHTE E-RECHNUNG IM EINGANG. ZUGFeRD/Factur-X, Profil EXTENDED, EN-16931-konform, TestIndicator=false; strukturierter Teil factur-x.xml im PDF/A-3 eingebettet. 11-Punkte-Pruefung nach § 14 UStG vollstaendig bestanden, Sicht- und XML-Teil stimmen ueberein. Einmalige Anschaffung — bewusst NICHT im Blatt Kostenuebersicht/Monatsverlauf, die nur laufende Kosten fuehren. Bestellt ueber die Privatadresse sk-holm@hotmail.de, kuenftig rechnung@sofortangebot.app verwenden. | T22: =ROUND(L22,2)
S23: Summe erfasste Vorsteuer 2026 (Reverse Charge steht mit 0, weil durchlaufend) → | T23: =ROUND(SUM(T5:T22),2)
S24: davon noch OFFEN — aus zwei verschiedenen Gruenden (Belege 2026-001, -009, -012) → | T24: =ROUND(T5+T13+T16,2)
S25: unstrittig abziehbar → | T25: =ROUND(T23-T24,2)
S26: KORREKTUR 17.09.2026 (Head of Finance), nach einem berechtigten Einwand von Sandy: Die erste Fassung dieser Zeilen hat 14,76 EUR als strittig gefuehrt und dabei die KLEINBETRAGSREGELUNG uebersehen. Nach § 33 UStDV braucht eine Rechnung bis 250 EUR brutto WEDER Namen NOCH Anschrift des Leistungsempfaengers — nur Lieferant, Datum, Leistung, Bruttobetrag und Steuersatz. Damit ist Beleg 2026-004 (OpenAI, "Hugo", 15,50 EUR brutto) vollstaendig abzugsfaehig, und bei den Apple-Belegen ist die abweichende Anschrift ebenfalls unschaedlich. Fast alle Belege dieses Betriebs liegen unter 250 EUR. ES BLEIBEN ZWEI ECHTE PUNKTE, beide KEINE Formfehler: (1) 2026-001 und 2026-009, Claude Pro ueber Apple, zusammen 7,02 EUR — offen ist die BETRIEBLICHE VERANLASSUNG (geschaeftlich oder privat genutzt), seit 02.09. vermerkt. (2) 2026-012, IONOS, 5,27 EUR — die Rechnung betrifft drei fremde Domains, Sofortangebot-Anteil 0,00 EUR, also insoweit keine betriebliche Veranlassung. Ausnahme von § 33 UStDV, die hier nicht greift: bei Reverse-Charge-Umsaetzen (§ 13b) gilt die Erleichterung NICHT — die Supabase-Belege brauchen weiter volle Angaben.
A37: Umrechnung USD → EUR — BMF-Umsatzsteuer-Umrechnungskurse (§ 16 Abs. 6 UStG)
A38: Monat 2026 | B38: Kurs (USD je 1 EUR)
A39: Mai | B39: 1.1673
A40: Juni | B40: 1.1518
A41: Juli | B41: 1.1417
A42: August | B42: 1.1593
A44: Maßgeblich ist der Monat des Rechnungsdatums (bei Supabase zugleich der Monat, in dem die Dauerleistung endet und die Steuer nach § 13b UStG entsteht). Quelle: BMF-Schreiben vom 01.09.2026, Gz. III C 3 - S 7329/00014/008/112, monatlich fortgeschriebene Übersicht 2026. Neuen Monat hier ergänzen — Spalte P rechnet dann von selbst. Für EUR-Belege verweist Spalte P unverändert auf den Bruttobetrag.

Sheet Monatsverlauf
A1: Monatsverlauf laufende Kosten
A2: Werte werden per Formel aus dem 'Rechnungsjournal' gezogen (nach Rechnungsmonat, Dienst und Währung) — beim Ergänzen neuer Belege im Journal aktualisiert sich diese Ansicht automatisch. Leere Zelle = noch kein Beleg für diesen Monat gefunden.
A4: Dienst | B4: Mai 2026 | C4: Jun 2026 | D4: Jul 2026 | E4: Aug 2026 | F4: Sep 2026 | G4: Okt 2026 | H4: Nov 2026 | I4: Dez 2026 | J4: Gesamt (Zeitraum)
A5: Supabase | B5: =IF(COUNTIFS(Rechnungsjournal!$G$5:$G$34,$A5,Rechnungsjournal!$B$5:$B$34,">="&DATE(2026,5,1),Rechnungsjournal!$B$5:$B$34,"<"&DATE(2026,6,1))=0,"",SUMIFS(Rechnungsjournal!$N$5:$N$34,Rechnungsjournal!$G$5:$G$34,$A5,Rechnungsjournal!$B$5:$B$34,">="&DATE(2026,5,1),Rechnungsjournal!$B$5:$B$34,"<"&DATE(2026,6,1))) | C5: =IF(COUNTIFS(Rechnungsjournal!$G$5:$G$34,$A5,Rechnungsjournal!$B$5:$B$34,">="&DATE(2026,6,1),Rechnungsjournal!$B$5:$B$34,"<"&DATE(2026,7,1))=0,"",SUMIFS(Rechnungsjournal!$N$5:$N$34,Rechnungsjournal!$G$5:$G$34,$A5,Rechnungsjournal!$B$5:$B$34,">="&DATE(2026,6,1),Rechnungsjournal!$B$5:$B$34,"<"&DATE(2026,7,1))) | D5: =IF(COUNTIFS(Rechnungsjournal!$G$5:$G$34,$A5,Rechnungsjournal!$B$5:$B$34,">="&DATE(2026,7,1),Rechnungsjournal!$B$5:$B$34,"<"&DATE(2026,8,1))=0,"",SUMIFS(Rechnungsjournal!$N$5:$N$34,Rechnungsjournal!$G$5:$G$34,$A5,Rechnungsjournal!$B$5:$B$34,">="&DATE(2026,7,1),Rechnungsjournal!$B$5:$B$34,"<"&DATE(2026,8,1))) | E5: =IF(COUNTIFS(Rechnungsjournal!$G$5:$G$34,$A5,Rechnungsjournal!$B$5:$B$34,">="&DATE(2026,8,1),Rechnungsjournal!$B$5:$B$34,"<"&DATE(2026,9,1))=0,"",SUMIFS(Rechnungsjournal!$N$5:$N$34,Rechnungsjournal!$G$5:$G$34,$A5,Rechnungsjournal!$B$5:$B$34,">="&DATE(2026,8,1),Rechnungsjournal!$B$5:$B$34,"<"&DATE(2026,9,1))) | F5: =IF(COUNTIFS(Rechnungsjournal!$G$5:$G$34,$A5,Rechnungsjournal!$B$5:$B$34,">="&DATE(2026,9,1),Rechnungsjournal!$B$5:$B$34,"<"&DATE(2026,10,1))=0,"",SUMIFS(Rechnungsjournal!$N$5:$N$34,Rechnungsjournal!$G$5:$G$34,$A5,Rechnungsjournal!$B$5:$B$34,">="&DATE(2026,9,1),Rechnungsjournal!$B$5:$B$34,"<"&DATE(2026,10,1))) | G5: =IF(COUNTIFS(Rechnungsjournal!$G$5:$G$34,$A5,Rechnungsjournal!$B$5:$B$34,">="&DATE(2026,10,1),Rechnungsjournal!$B$5:$B$34,"<"&DATE(2026,11,1))=0,"",SUMIFS(Rechnungsjournal!$N$5:$N$34,Rechnungsjournal!$G$5:$G$34,$A5,Rechnungsjournal!$B$5:$B$34,">="&DATE(2026,10,1),Rechnungsjournal!$B$5:$B$34,"<"&DATE(2026,11,1))) | H5: =IF(COUNTIFS(Rechnungsjournal!$G$5:$G$34,$A5,Rechnungsjournal!$B$5:$B$34,">="&DATE(2026,11,1),Rechnungsjournal!$B$5:$B$34,"<"&DATE(2026,12,1))=0,"",SUMIFS(Rechnungsjournal!$N$5:$N$34,Rechnungsjournal!$G$5:$G$34,$A5,Rechnungsjournal!$B$5:$B$34,">="&DATE(2026,11,1),Rechnungsjournal!$B$5:$B$34,"<"&DATE(2026,12,1))) | I5: =IF(COUNTIFS(Rechnungsjournal!$G$5:$G$34,$A5,Rechnungsjournal!$B$5:$B$34,">="&DATE(2026,12,1),Rechnungsjournal!$B$5:$B$34,"<"&DATE(2027,1,1))=0,"",SUMIFS(Rechnungsjournal!$N$5:$N$34,Rechnungsjournal!$G$5:$G$34,$A5,Rechnungsjournal!$B$5:$B$34,">="&DATE(2026,12,1),Rechnungsjournal!$B$5:$B$34,"<"&DATE(2027,1,1))) | J5: =SUM(B5:I5)
A6: Vercel | B6: =IF(COUNTIFS(Rechnungsjournal!$G$5:$G$34,$A6,Rechnungsjournal!$B$5:$B$34,">="&DATE(2026,5,1),Rechnungsjournal!$B$5:$B$34,"<"&DATE(2026,6,1))=0,"",SUMIFS(Rechnungsjournal!$N$5:$N$34,Rechnungsjournal!$G$5:$G$34,$A6,Rechnungsjournal!$B$5:$B$34,">="&DATE(2026,5,1),Rechnungsjournal!$B$5:$B$34,"<"&DATE(2026,6,1))) | C6: =IF(COUNTIFS(Rechnungsjournal!$G$5:$G$34,$A6,Rechnungsjournal!$B$5:$B$34,">="&DATE(2026,6,1),Rechnungsjournal!$B$5:$B$34,"<"&DATE(2026,7,1))=0,"",SUMIFS(Rechnungsjournal!$N$5:$N$34,Rechnungsjournal!$G$5:$G$34,$A6,Rechnungsjournal!$B$5:$B$34,">="&DATE(2026,6,1),Rechnungsjournal!$B$5:$B$34,"<"&DATE(2026,7,1))) | D6: =IF(COUNTIFS(Rechnungsjournal!$G$5:$G$34,$A6,Rechnungsjournal!$B$5:$B$34,">="&DATE(2026,7,1),Rechnungsjournal!$B$5:$B$34,"<"&DATE(2026,8,1))=0,"",SUMIFS(Rechnungsjournal!$N$5:$N$34,Rechnungsjournal!$G$5:$G$34,$A6,Rechnungsjournal!$B$5:$B$34,">="&DATE(2026,7,1),Rechnungsjournal!$B$5:$B$34,"<"&DATE(2026,8,1))) | E6: =IF(COUNTIFS(Rechnungsjournal!$G$5:$G$34,$A6,Rechnungsjournal!$B$5:$B$34,">="&DATE(2026,8,1),Rechnungsjournal!$B$5:$B$34,"<"&DATE(2026,9,1))=0,"",SUMIFS(Rechnungsjournal!$N$5:$N$34,Rechnungsjournal!$G$5:$G$34,$A6,Rechnungsjournal!$B$5:$B$34,">="&DATE(2026,8,1),Rechnungsjournal!$B$5:$B$34,"<"&DATE(2026,9,1))) | F6: =IF(COUNTIFS(Rechnungsjournal!$G$5:$G$34,$A6,Rechnungsjournal!$B$5:$B$34,">="&DATE(2026,9,1),Rechnungsjournal!$B$5:$B$34,"<"&DATE(2026,10,1))=0,"",SUMIFS(Rechnungsjournal!$N$5:$N$34,Rechnungsjournal!$G$5:$G$34,$A6,Rechnungsjournal!$B$5:$B$34,">="&DATE(2026,9,1),Rechnungsjournal!$B$5:$B$34,"<"&DATE(2026,10,1))) | G6: =IF(COUNTIFS(Rechnungsjournal!$G$5:$G$34,$A6,Rechnungsjournal!$B$5:$B$34,">="&DATE(2026,10,1),Rechnungsjournal!$B$5:$B$34,"<"&DATE(2026,11,1))=0,"",SUMIFS(Rechnungsjournal!$N$5:$N$34,Rechnungsjournal!$G$5:$G$34,$A6,Rechnungsjournal!$B$5:$B$34,">="&DATE(2026,10,1),Rechnungsjournal!$B$5:$B$34,"<"&DATE(2026,11,1))) | H6: =IF(COUNTIFS(Rechnungsjournal!$G$5:$G$34,$A6,Rechnungsjournal!$B$5:$B$34,">="&DATE(2026,11,1),Rechnungsjournal!$B$5:$B$34,"<"&DATE(2026,12,1))=0,"",SUMIFS(Rechnungsjournal!$N$5:$N$34,Rechnungsjournal!$G$5:$G$34,$A6,Rechnungsjournal!$B$5:$B$34,">="&DATE(2026,11,1),Rechnungsjournal!$B$5:$B$34,"<"&DATE(2026,12,1))) | I6: =IF(COUNTIFS(Rechnungsjournal!$G$5:$G$34,$A6,Rechnungsjournal!$B$5:$B$34,">="&DATE(2026,12,1),Rechnungsjournal!$B$5:$B$34,"<"&DATE(2027,1,1))=0,"",SUMIFS(Rechnungsjournal!$N$5:$N$34,Rechnungsjournal!$G$5:$G$34,$A6,Rechnungsjournal!$B$5:$B$34,">="&DATE(2026,12,1),Rechnungsjournal!$B$5:$B$34,"<"&DATE(2027,1,1))) | J6: =SUM(B6:I6)
A7: Anthropic — direkt | B7: =IF(COUNTIFS(Rechnungsjournal!$G$5:$G$34,$A7,Rechnungsjournal!$B$5:$B$34,">="&DATE(2026,5,1),Rechnungsjournal!$B$5:$B$34,"<"&DATE(2026,6,1))=0,"",SUMIFS(Rechnungsjournal!$N$5:$N$34,Rechnungsjournal!$G$5:$G$34,$A7,Rechnungsjournal!$B$5:$B$34,">="&DATE(2026,5,1),Rechnungsjournal!$B$5:$B$34,"<"&DATE(2026,6,1))) | C7: =IF(COUNTIFS(Rechnungsjournal!$G$5:$G$34,$A7,Rechnungsjournal!$B$5:$B$34,">="&DATE(2026,6,1),Rechnungsjournal!$B$5:$B$34,"<"&DATE(2026,7,1))=0,"",SUMIFS(Rechnungsjournal!$N$5:$N$34,Rechnungsjournal!$G$5:$G$34,$A7,Rechnungsjournal!$B$5:$B$34,">="&DATE(2026,6,1),Rechnungsjournal!$B$5:$B$34,"<"&DATE(2026,7,1))) | D7: =IF(COUNTIFS(Rechnungsjournal!$G$5:$G$34,$A7,Rechnungsjournal!$B$5:$B$34,">="&DATE(2026,7,1),Rechnungsjournal!$B$5:$B$34,"<"&DATE(2026,8,1))=0,"",SUMIFS(Rechnungsjournal!$N$5:$N$34,Rechnungsjournal!$G$5:$G$34,$A7,Rechnungsjournal!$B$5:$B$34,">="&DATE(2026,7,1),Rechnungsjournal!$B$5:$B$34,"<"&DATE(2026,8,1))) | E7: =IF(COUNTIFS(Rechnungsjournal!$G$5:$G$34,$A7,Rechnungsjournal!$B$5:$B$34,">="&DATE(2026,8,1),Rechnungsjournal!$B$5:$B$34,"<"&DATE(2026,9,1))=0,"",SUMIFS(Rechnungsjournal!$N$5:$N$34,Rechnungsjournal!$G$5:$G$34,$A7,Rechnungsjournal!$B$5:$B$34,">="&DATE(2026,8,1),Rechnungsjournal!$B$5:$B$34,"<"&DATE(2026,9,1))) | F7: =IF(COUNTIFS(Rechnungsjournal!$G$5:$G$34,$A7,Rechnungsjournal!$B$5:$B$34,">="&DATE(2026,9,1),Rechnungsjournal!$B$5:$B$34,"<"&DATE(2026,10,1))=0,"",SUMIFS(Rechnungsjournal!$N$5:$N$34,Rechnungsjournal!$G$5:$G$34,$A7,Rechnungsjournal!$B$5:$B$34,">="&DATE(2026,9,1),Rechnungsjournal!$B$5:$B$34,"<"&DATE(2026,10,1))) | G7: =IF(COUNTIFS(Rechnungsjournal!$G$5:$G$34,$A7,Rechnungsjournal!$B$5:$B$34,">="&DATE(2026,10,1),Rechnungsjournal!$B$5:$B$34,"<"&DATE(2026,11,1))=0,"",SUMIFS(Rechnungsjournal!$N$5:$N$34,Rechnungsjournal!$G$5:$G$34,$A7,Rechnungsjournal!$B$5:$B$34,">="&DATE(2026,10,1),Rechnungsjournal!$B$5:$B$34,"<"&DATE(2026,11,1))) | H7: =IF(COUNTIFS(Rechnungsjournal!$G$5:$G$34,$A7,Rechnungsjournal!$B$5:$B$34,">="&DATE(2026,11,1),Rechnungsjournal!$B$5:$B$34,"<"&DATE(2026,12,1))=0,"",SUMIFS(Rechnungsjournal!$N$5:$N$34,Rechnungsjournal!$G$5:$G$34,$A7,Rechnungsjournal!$B$5:$B$34,">="&DATE(2026,11,1),Rechnungsjournal!$B$5:$B$34,"<"&DATE(2026,12,1))) | I7: =IF(COUNTIFS(Rechnungsjournal!$G$5:$G$34,$A7,Rechnungsjournal!$B$5:$B$34,">="&DATE(2026,12,1),Rechnungsjournal!$B$5:$B$34,"<"&DATE(2027,1,1))=0,"",SUMIFS(Rechnungsjournal!$N$5:$N$34,Rechnungsjournal!$G$5:$G$34,$A7,Rechnungsjournal!$B$5:$B$34,">="&DATE(2026,12,1),Rechnungsjournal!$B$5:$B$34,"<"&DATE(2027,1,1))) | J7: =SUM(B7:I7)
A8: Claude Pro (Apple/iTunes) | B8: =IF(COUNTIFS(Rechnungsjournal!$G$5:$G$34,$A8,Rechnungsjournal!$B$5:$B$34,">="&DATE(2026,5,1),Rechnungsjournal!$B$5:$B$34,"<"&DATE(2026,6,1))=0,"",SUMIFS(Rechnungsjournal!$N$5:$N$34,Rechnungsjournal!$G$5:$G$34,$A8,Rechnungsjournal!$B$5:$B$34,">="&DATE(2026,5,1),Rechnungsjournal!$B$5:$B$34,"<"&DATE(2026,6,1))) | C8: =IF(COUNTIFS(Rechnungsjournal!$G$5:$G$34,$A8,Rechnungsjournal!$B$5:$B$34,">="&DATE(2026,6,1),Rechnungsjournal!$B$5:$B$34,"<"&DATE(2026,7,1))=0,"",SUMIFS(Rechnungsjournal!$N$5:$N$34,Rechnungsjournal!$G$5:$G$34,$A8,Rechnungsjournal!$B$5:$B$34,">="&DATE(2026,6,1),Rechnungsjournal!$B$5:$B$34,"<"&DATE(2026,7,1))) | D8: =IF(COUNTIFS(Rechnungsjournal!$G$5:$G$34,$A8,Rechnungsjournal!$B$5:$B$34,">="&DATE(2026,7,1),Rechnungsjournal!$B$5:$B$34,"<"&DATE(2026,8,1))=0,"",SUMIFS(Rechnungsjournal!$N$5:$N$34,Rechnungsjournal!$G$5:$G$34,$A8,Rechnungsjournal!$B$5:$B$34,">="&DATE(2026,7,1),Rechnungsjournal!$B$5:$B$34,"<"&DATE(2026,8,1))) | E8: =IF(COUNTIFS(Rechnungsjournal!$G$5:$G$34,$A8,Rechnungsjournal!$B$5:$B$34,">="&DATE(2026,8,1),Rechnungsjournal!$B$5:$B$34,"<"&DATE(2026,9,1))=0,"",SUMIFS(Rechnungsjournal!$N$5:$N$34,Rechnungsjournal!$G$5:$G$34,$A8,Rechnungsjournal!$B$5:$B$34,">="&DATE(2026,8,1),Rechnungsjournal!$B$5:$B$34,"<"&DATE(2026,9,1))) | F8: =IF(COUNTIFS(Rechnungsjournal!$G$5:$G$34,$A8,Rechnungsjournal!$B$5:$B$34,">="&DATE(2026,9,1),Rechnungsjournal!$B$5:$B$34,"<"&DATE(2026,10,1))=0,"",SUMIFS(Rechnungsjournal!$N$5:$N$34,Rechnungsjournal!$G$5:$G$34,$A8,Rechnungsjournal!$B$5:$B$34,">="&DATE(2026,9,1),Rechnungsjournal!$B$5:$B$34,"<"&DATE(2026,10,1))) | G8: =IF(COUNTIFS(Rechnungsjournal!$G$5:$G$34,$A8,Rechnungsjournal!$B$5:$B$34,">="&DATE(2026,10,1),Rechnungsjournal!$B$5:$B$34,"<"&DATE(2026,11,1))=0,"",SUMIFS(Rechnungsjournal!$N$5:$N$34,Rechnungsjournal!$G$5:$G$34,$A8,Rechnungsjournal!$B$5:$B$34,">="&DATE(2026,10,1),Rechnungsjournal!$B$5:$B$34,"<"&DATE(2026,11,1))) | H8: =IF(COUNTIFS(Rechnungsjournal!$G$5:$G$34,$A8,Rechnungsjournal!$B$5:$B$34,">="&DATE(2026,11,1),Rechnungsjournal!$B$5:$B$34,"<"&DATE(2026,12,1))=0,"",SUMIFS(Rechnungsjournal!$N$5:$N$34,Rechnungsjournal!$G$5:$G$34,$A8,Rechnungsjournal!$B$5:$B$34,">="&DATE(2026,11,1),Rechnungsjournal!$B$5:$B$34,"<"&DATE(2026,12,1))) | I8: =IF(COUNTIFS(Rechnungsjournal!$G$5:$G$34,$A8,Rechnungsjournal!$B$5:$B$34,">="&DATE(2026,12,1),Rechnungsjournal!$B$5:$B$34,"<"&DATE(2027,1,1))=0,"",SUMIFS(Rechnungsjournal!$N$5:$N$34,Rechnungsjournal!$G$5:$G$34,$A8,Rechnungsjournal!$B$5:$B$34,">="&DATE(2026,12,1),Rechnungsjournal!$B$5:$B$34,"<"&DATE(2027,1,1))) | J8: =SUM(B8:I8)
A9: OpenAI | B9: =IF(COUNTIFS(Rechnungsjournal!$G$5:$G$34,$A9,Rechnungsjournal!$B$5:$B$34,">="&DATE(2026,5,1),Rechnungsjournal!$B$5:$B$34,"<"&DATE(2026,6,1))=0,"",SUMIFS(Rechnungsjournal!$N$5:$N$34,Rechnungsjournal!$G$5:$G$34,$A9,Rechnungsjournal!$B$5:$B$34,">="&DATE(2026,5,1),Rechnungsjournal!$B$5:$B$34,"<"&DATE(2026,6,1))) | C9: =IF(COUNTIFS(Rechnungsjournal!$G$5:$G$34,$A9,Rechnungsjournal!$B$5:$B$34,">="&DATE(2026,6,1),Rechnungsjournal!$B$5:$B$34,"<"&DATE(2026,7,1))=0,"",SUMIFS(Rechnungsjournal!$N$5:$N$34,Rechnungsjournal!$G$5:$G$34,$A9,Rechnungsjournal!$B$5:$B$34,">="&DATE(2026,6,1),Rechnungsjournal!$B$5:$B$34,"<"&DATE(2026,7,1))) | D9: =IF(COUNTIFS(Rechnungsjournal!$G$5:$G$34,$A9,Rechnungsjournal!$B$5:$B$34,">="&DATE(2026,7,1),Rechnungsjournal!$B$5:$B$34,"<"&DATE(2026,8,1))=0,"",SUMIFS(Rechnungsjournal!$N$5:$N$34,Rechnungsjournal!$G$5:$G$34,$A9,Rechnungsjournal!$B$5:$B$34,">="&DATE(2026,7,1),Rechnungsjournal!$B$5:$B$34,"<"&DATE(2026,8,1))) | E9: =IF(COUNTIFS(Rechnungsjournal!$G$5:$G$34,$A9,Rechnungsjournal!$B$5:$B$34,">="&DATE(2026,8,1),Rechnungsjournal!$B$5:$B$34,"<"&DATE(2026,9,1))=0,"",SUMIFS(Rechnungsjournal!$N$5:$N$34,Rechnungsjournal!$G$5:$G$34,$A9,Rechnungsjournal!$B$5:$B$34,">="&DATE(2026,8,1),Rechnungsjournal!$B$5:$B$34,"<"&DATE(2026,9,1))) | F9: =IF(COUNTIFS(Rechnungsjournal!$G$5:$G$34,$A9,Rechnungsjournal!$B$5:$B$34,">="&DATE(2026,9,1),Rechnungsjournal!$B$5:$B$34,"<"&DATE(2026,10,1))=0,"",SUMIFS(Rechnungsjournal!$N$5:$N$34,Rechnungsjournal!$G$5:$G$34,$A9,Rechnungsjournal!$B$5:$B$34,">="&DATE(2026,9,1),Rechnungsjournal!$B$5:$B$34,"<"&DATE(2026,10,1))) | G9: =IF(COUNTIFS(Rechnungsjournal!$G$5:$G$34,$A9,Rechnungsjournal!$B$5:$B$34,">="&DATE(2026,10,1),Rechnungsjournal!$B$5:$B$34,"<"&DATE(2026,11,1))=0,"",SUMIFS(Rechnungsjournal!$N$5:$N$34,Rechnungsjournal!$G$5:$G$34,$A9,Rechnungsjournal!$B$5:$B$34,">="&DATE(2026,10,1),Rechnungsjournal!$B$5:$B$34,"<"&DATE(2026,11,1))) | H9: =IF(COUNTIFS(Rechnungsjournal!$G$5:$G$34,$A9,Rechnungsjournal!$B$5:$B$34,">="&DATE(2026,11,1),Rechnungsjournal!$B$5:$B$34,"<"&DATE(2026,12,1))=0,"",SUMIFS(Rechnungsjournal!$N$5:$N$34,Rechnungsjournal!$G$5:$G$34,$A9,Rechnungsjournal!$B$5:$B$34,">="&DATE(2026,11,1),Rechnungsjournal!$B$5:$B$34,"<"&DATE(2026,12,1))) | I9: =IF(COUNTIFS(Rechnungsjournal!$G$5:$G$34,$A9,Rechnungsjournal!$B$5:$B$34,">="&DATE(2026,12,1),Rechnungsjournal!$B$5:$B$34,"<"&DATE(2027,1,1))=0,"",SUMIFS(Rechnungsjournal!$N$5:$N$34,Rechnungsjournal!$G$5:$G$34,$A9,Rechnungsjournal!$B$5:$B$34,">="&DATE(2026,12,1),Rechnungsjournal!$B$5:$B$34,"<"&DATE(2027,1,1))) | J9: =SUM(B9:I9)
A10: Resend | J10: =SUM(B10:I10)
A11: Domain sofortangebot.app | B11: =IF(COUNTIFS(Rechnungsjournal!$G$5:$G$34,$A11,Rechnungsjournal!$B$5:$B$34,">="&DATE(2026,5,1),Rechnungsjournal!$B$5:$B$34,"<"&DATE(2026,6,1))=0,"",SUMIFS(Rechnungsjournal!$N$5:$N$34,Rechnungsjournal!$G$5:$G$34,$A11,Rechnungsjournal!$B$5:$B$34,">="&DATE(2026,5,1),Rechnungsjournal!$B$5:$B$34,"<"&DATE(2026,6,1))) | C11: =IF(COUNTIFS(Rechnungsjournal!$G$5:$G$34,$A11,Rechnungsjournal!$B$5:$B$34,">="&DATE(2026,6,1),Rechnungsjournal!$B$5:$B$34,"<"&DATE(2026,7,1))=0,"",SUMIFS(Rechnungsjournal!$N$5:$N$34,Rechnungsjournal!$G$5:$G$34,$A11,Rechnungsjournal!$B$5:$B$34,">="&DATE(2026,6,1),Rechnungsjournal!$B$5:$B$34,"<"&DATE(2026,7,1))) | D11: =IF(COUNTIFS(Rechnungsjournal!$G$5:$G$34,$A11,Rechnungsjournal!$B$5:$B$34,">="&DATE(2026,7,1),Rechnungsjournal!$B$5:$B$34,"<"&DATE(2026,8,1))=0,"",SUMIFS(Rechnungsjournal!$N$5:$N$34,Rechnungsjournal!$G$5:$G$34,$A11,Rechnungsjournal!$B$5:$B$34,">="&DATE(2026,7,1),Rechnungsjournal!$B$5:$B$34,"<"&DATE(2026,8,1))) | E11: =IF(COUNTIFS(Rechnungsjournal!$G$5:$G$34,$A11,Rechnungsjournal!$B$5:$B$34,">="&DATE(2026,8,1),Rechnungsjournal!$B$5:$B$34,"<"&DATE(2026,9,1))=0,"",SUMIFS(Rechnungsjournal!$N$5:$N$34,Rechnungsjournal!$G$5:$G$34,$A11,Rechnungsjournal!$B$5:$B$34,">="&DATE(2026,8,1),Rechnungsjournal!$B$5:$B$34,"<"&DATE(2026,9,1))) | F11: =IF(COUNTIFS(Rechnungsjournal!$G$5:$G$34,$A11,Rechnungsjournal!$B$5:$B$34,">="&DATE(2026,9,1),Rechnungsjournal!$B$5:$B$34,"<"&DATE(2026,10,1))=0,"",SUMIFS(Rechnungsjournal!$N$5:$N$34,Rechnungsjournal!$G$5:$G$34,$A11,Rechnungsjournal!$B$5:$B$34,">="&DATE(2026,9,1),Rechnungsjournal!$B$5:$B$34,"<"&DATE(2026,10,1))) | G11: =IF(COUNTIFS(Rechnungsjournal!$G$5:$G$34,$A11,Rechnungsjournal!$B$5:$B$34,">="&DATE(2026,10,1),Rechnungsjournal!$B$5:$B$34,"<"&DATE(2026,11,1))=0,"",SUMIFS(Rechnungsjournal!$N$5:$N$34,Rechnungsjournal!$G$5:$G$34,$A11,Rechnungsjournal!$B$5:$B$34,">="&DATE(2026,10,1),Rechnungsjournal!$B$5:$B$34,"<"&DATE(2026,11,1))) | H11: =IF(COUNTIFS(Rechnungsjournal!$G$5:$G$34,$A11,Rechnungsjournal!$B$5:$B$34,">="&DATE(2026,11,1),Rechnungsjournal!$B$5:$B$34,"<"&DATE(2026,12,1))=0,"",SUMIFS(Rechnungsjournal!$N$5:$N$34,Rechnungsjournal!$G$5:$G$34,$A11,Rechnungsjournal!$B$5:$B$34,">="&DATE(2026,11,1),Rechnungsjournal!$B$5:$B$34,"<"&DATE(2026,12,1))) | I11: =IF(COUNTIFS(Rechnungsjournal!$G$5:$G$34,$A11,Rechnungsjournal!$B$5:$B$34,">="&DATE(2026,12,1),Rechnungsjournal!$B$5:$B$34,"<"&DATE(2027,1,1))=0,"",SUMIFS(Rechnungsjournal!$N$5:$N$34,Rechnungsjournal!$G$5:$G$34,$A11,Rechnungsjournal!$B$5:$B$34,">="&DATE(2026,12,1),Rechnungsjournal!$B$5:$B$34,"<"&DATE(2027,1,1))) | J11: =SUM(B11:I11)
A12: Sentry | J12: =SUM(B12:I12)
A13: Stripe | J13: =SUM(B13:I13)
A14: GitHub Actions (Backup-Artefakte) | J14: =SUM(B14:I14)
A16: Monatssumme USD | B16: =IF(B5="",0,B5)+IF(B6="",0,B6)+IF(B7="",0,B7)+IF(B9="",0,B9) | C16: =IF(C5="",0,C5)+IF(C6="",0,C6)+IF(C7="",0,C7)+IF(C9="",0,C9) | D16: =IF(D5="",0,D5)+IF(D6="",0,D6)+IF(D7="",0,D7)+IF(D9="",0,D9) | E16: =IF(E5="",0,E5)+IF(E6="",0,E6)+IF(E7="",0,E7)+IF(E9="",0,E9) | F16: =IF(F5="",0,F5)+IF(F6="",0,F6)+IF(F7="",0,F7)+IF(F9="",0,F9) | G16: =IF(G5="",0,G5)+IF(G6="",0,G6)+IF(G7="",0,G7)+IF(G9="",0,G9) | H16: =IF(H5="",0,H5)+IF(H6="",0,H6)+IF(H7="",0,H7)+IF(H9="",0,H9) | I16: =IF(I5="",0,I5)+IF(I6="",0,I6)+IF(I7="",0,I7)+IF(I9="",0,I9)
A17: Monatssumme EUR | B17: =IF(B8="",0,B8)+IF(B11="",0,B11) | C17: =IF(C8="",0,C8)+IF(C11="",0,C11) | D17: =IF(D8="",0,D8)+IF(D11="",0,D11) | E17: =IF(E8="",0,E8)+IF(E11="",0,E11) | F17: =IF(F8="",0,F8)+IF(F11="",0,F11) | G17: =IF(G8="",0,G8)+IF(G11="",0,G11) | H17: =IF(H8="",0,H8)+IF(H11="",0,H11) | I17: =IF(I8="",0,I8)+IF(I11="",0,I11)

Sheet Plan-Deckblatt
A1: Finanzplan Sofortangebot — Deckblatt (Fassung 2, 03.09.2026)
A2: Die Zahlen, die Sandy braucht, je Szenario. Alles Weitere ist Beleg: 'Plan-Annahmen' (alle Eingaben, gelb) · 'Plan-Kunden' (Kanalmodell und Zeitbudget) · 'Plan-Kosten' (Vollständigkeits-Katalog A–H) · 'Plan-24M' (Monatsraster) · 'Plan-Phase B' (Ausstiegsstufen). Diese Fassung rechnet mit der Rechtsform-Entscheidung vom Abend des 03.09.2026: Einzelunternehmen ab Oktober 2026, UG erst bei rund 20 zahlenden Betrieben. Die erste Fassung (UG ab Monat 1) ist ersetzt — der Vergleich steht unten, die Begründung in docs/chief-of-staff-finance-todos.md.
A6: Was der Plan jetzt kostet statt vorher: 15 € Gründung statt rund 1.700 € (Notar, Handelsregister, Stammkapital) und 800 €/Jahr Buchhaltung statt 3.000 €/Jahr — solange Sandy Einzelunternehmerin ist. Gewerbesteuer und IHK-Beitrag fallen im ganzen Horizont weg (Freibetrag § 11 GewStG, Gründerbefreiung § 3 Abs. 3 IHKG). — Nachtrag 17.09.2026: Mit der Regelbesteuerung sinken die laufenden Kosten um rund 17 €/Monat (Vorsteuer auf Lexware, Vercel, Anthropic, Claude Pro, IONOS). Das verschiebt den Break-even im realistischen Szenario NICHT (weiter Monat 11), verbessert aber den Tiefpunkt der Liquiditaet um rund 300 € und im vorsichtigen Szenario den ersten profitablen Monat von 23 auf 21.
A8: Szenario | B8: Vorsichtig | C8: Realistisch | D8: Optimistisch
A9: Neukunden aus dem Kanalplan (Σ 24 Monate, Marketing) | B9: ='Plan-Kunden'!$C$32 | C9: ='Plan-Kunden'!$C$61 | D9: ='Plan-Kunden'!$C$90
A10: davon zusätzlich durch Mundpropaganda | B10: ='Plan-Kunden'!$D$32 | C10: ='Plan-Kunden'!$D$61 | D10: ='Plan-Kunden'!$D$90
A11: Abwanderung Standardkunden pro Monat (Annahme) | B11: ='Plan-Annahmen'!$B$44 | C11: ='Plan-Annahmen'!$B$45 | D11: ='Plan-Annahmen'!$B$46
A12: Zahlende Betriebe am Ende (Monat 24) | B12: ='Plan-Kunden'!$K$32 | C12: ='Plan-Kunden'!$K$61 | D12: ='Plan-Kunden'!$K$90
A14: 1) Wann trägt es sich?
A15: Erster Monat mit positivem Monatsergebnis — NEUE Fassung | B15: =IFERROR(INDEX('Plan-24M'!$A$8:$A$31,MATCH(1,'Plan-24M'!$X$8:$X$31,0)),"> 24 Monate") | C15: =IFERROR(INDEX('Plan-24M'!$A$37:$A$60,MATCH(1,'Plan-24M'!$X$37:$X$60,0)),"> 24 Monate") | D15: =IFERROR(INDEX('Plan-24M'!$A$66:$A$89,MATCH(1,'Plan-24M'!$X$66:$X$89,0)),"> 24 Monate")
A16: … alte Fassung (UG ab Monat 1) | B16: > 24 Monate | C16: 15 | D16: 11
A17: … Kalendermonat | B17: =IFERROR(INDEX('Plan-24M'!$B$8:$B$31,MATCH(1,'Plan-24M'!$X$8:$X$31,0)),"> 24 Monate") | C17: =IFERROR(INDEX('Plan-24M'!$B$37:$B$60,MATCH(1,'Plan-24M'!$X$37:$X$60,0)),"> 24 Monate") | D17: =IFERROR(INDEX('Plan-24M'!$B$66:$B$89,MATCH(1,'Plan-24M'!$X$66:$X$89,0)),"> 24 Monate")
A18: … zahlende Betriebe in diesem Monat | B18: =IFERROR(INDEX('Plan-24M'!$D$8:$D$31,MATCH(1,'Plan-24M'!$X$8:$X$31,0)),"> 24 Monate") | C18: =IFERROR(INDEX('Plan-24M'!$D$37:$D$60,MATCH(1,'Plan-24M'!$X$37:$X$60,0)),"> 24 Monate") | D18: =IFERROR(INDEX('Plan-24M'!$D$66:$D$89,MATCH(1,'Plan-24M'!$X$66:$X$89,0)),"> 24 Monate")
A19: Umsatz Monat 24 (netto) | B19: ='Plan-24M'!$H$31 | C19: ='Plan-24M'!$H$60 | D19: ='Plan-24M'!$H$89
A20: Umsatz Jahr 1 (Sep 26 – Aug 27) | B20: =SUM('Plan-24M'!$H$8:$H$19) | C20: =SUM('Plan-24M'!$H$37:$H$48) | D20: =SUM('Plan-24M'!$H$66:$H$77)
A21: Umsatz Jahr 2 (Sep 27 – Aug 28) | B21: =SUM('Plan-24M'!$H$20:$H$31) | C21: =SUM('Plan-24M'!$H$49:$H$60) | D21: =SUM('Plan-24M'!$H$78:$H$89)
A23: 2) Wie viel muss Sandy vorstrecken? (mit Vorher/Nachher)
A24: Tiefpunkt der Liquidität — NEUE Fassung (Einzelunternehmen) | B24: =MIN(0,MIN('Plan-24M'!$W$8:$W$31)) | C24: =MIN(0,MIN('Plan-24M'!$W$37:$W$60)) | D24: =MIN(0,MIN('Plan-24M'!$W$66:$W$89))
A25: Tiefpunkt der Liquidität — alte Fassung (UG ab Monat 1) | B25: -14260 | C25: -9280 | D25: -7860
A26: Ersparnis gegenüber der alten Fassung | B26: =B24-B25 | C26: =C24-C25 | D26: =D24-D25
A27: … davon Reserven, die Vermögen bleiben | B27: ='Plan-24M'!$V$31 | C27: ='Plan-24M'!$V$60 | D27: ='Plan-24M'!$V$89
A28: … Monat des Tiefpunkts | B28: =MATCH(MIN('Plan-24M'!$W$8:$W$31),'Plan-24M'!$W$8:$W$31,0) | C28: =MATCH(MIN('Plan-24M'!$W$37:$W$60),'Plan-24M'!$W$37:$W$60,0) | D28: =MATCH(MIN('Plan-24M'!$W$66:$W$89),'Plan-24M'!$W$66:$W$89,0)
A29: Erster Monat mit dauerhaft positiver Liquidität | B29: =IFERROR(INDEX('Plan-24M'!$A$8:$A$31,MATCH(1,'Plan-24M'!$AD$8:$AD$31,0)),"> 24 Monate") | C29: =IFERROR(INDEX('Plan-24M'!$A$37:$A$60,MATCH(1,'Plan-24M'!$AD$37:$AD$60,0)),"> 24 Monate") | D29: =IFERROR(INDEX('Plan-24M'!$A$66:$A$89,MATCH(1,'Plan-24M'!$AD$66:$AD$89,0)),"> 24 Monate")
A30: Kumuliertes Ergebnis nach Steuerrücklage, Monat 24 | B30: ='Plan-24M'!$U$31 | C30: ='Plan-24M'!$U$60 | D30: ='Plan-24M'!$U$89
A32: 3) Wann wird aus dem Einzelunternehmen eine UG?
A33: UG-Monat (erste 20 aktive Betriebe) | B33: =IF('Plan-24M'!$O$6=999,"> 24 Monate",'Plan-24M'!$O$6) | C33: =IF('Plan-24M'!$O$35=999,"> 24 Monate",'Plan-24M'!$O$35) | D33: =IF('Plan-24M'!$O$64=999,"> 24 Monate",'Plan-24M'!$O$64)
A34: … Kalendermonat | B34: =IF('Plan-24M'!$O$6=999,"> 24 Monate",EDATE('Plan-Annahmen'!$B$8,'Plan-24M'!$O$6-1)) | C34: =IF('Plan-24M'!$O$35=999,"> 24 Monate",EDATE('Plan-Annahmen'!$B$8,'Plan-24M'!$O$35-1)) | D34: =IF('Plan-24M'!$O$64=999,"> 24 Monate",EDATE('Plan-Annahmen'!$B$8,'Plan-24M'!$O$64-1))
A35: … Notartermin spätestens im Monat (4–6 Wochen Vorlauf) | B35: =IF('Plan-24M'!$O$6=999,"> 24 Monate",'Plan-24M'!$O$6-1) | C35: =IF('Plan-24M'!$O$35=999,"> 24 Monate",'Plan-24M'!$O$35-1) | D35: =IF('Plan-24M'!$O$64=999,"> 24 Monate",'Plan-24M'!$O$64-1)
A36: Zusätzliche Kosten ab diesem Monat (€/Monat) | B36: =IF('Plan-24M'!$O$6=999,0,'Plan-Kosten'!$F$71) | C36: =IF('Plan-24M'!$O$35=999,0,'Plan-Kosten'!$F$71) | D36: =IF('Plan-24M'!$O$64=999,0,'Plan-Kosten'!$F$71)
A37: Einmalig im UG-Monat (Notar, Eröffnungsbilanz) | B37: =IF('Plan-24M'!$O$6=999,0,'Plan-Kosten'!$F$72) | C37: =IF('Plan-24M'!$O$35=999,0,'Plan-Kosten'!$F$72) | D37: =IF('Plan-24M'!$O$64=999,0,'Plan-Kosten'!$F$72)
A38: Zusätzlich gebunden: Stammkapital | B38: =IF('Plan-24M'!$O$6=999,0,'Plan-Kosten'!$F$73) | C38: =IF('Plan-24M'!$O$35=999,0,'Plan-Kosten'!$F$73) | D38: =IF('Plan-24M'!$O$64=999,0,'Plan-Kosten'!$F$73)
A40: Ab dem UG-Monat gilt mein Vorbehalt zur Besteuerung wieder: Das Raster rechnet die Steuer wie beim Einzelunternehmen (Gewinn oben auf Sandys Gehalt). Für die Einzelunternehmens-Phase ist das korrekt; ab der UG kämen Körperschaft- und Gewerbesteuer auf Gesellschaftsebene und danach Gehalt oder Ausschüttung — eine Steuerberater-Rechnung. Im vorsichtigen Szenario wird die UG im Horizont gar nicht erreicht, dort ist der Vorbehalt gegenstandslos.
A42: 4) Ab wann kann Sandy reduzieren — und ganz aufhören?
A43: Der Ausstieg ist eine Treppe: In Stufe B1 läuft das Teilzeitgehalt weiter und die Krankenversicherung bleibt beim Arbeitgeber — Sofortangebot muss nur die Lücke zu 2.500 € netto schließen. Erst in B2 kommt alles zusammen.
A45: WICHTIG, und anders als erwartet: Die Ausstiegs-Treppe bewegt sich durch die Rechtsform-Entscheidung NICHT — die Zahlen der alten und der neuen Fassung sind identisch. Der Grund: Jede Ausstiegsstufe verlangt mindestens 37 zahlende Betriebe und liegt damit weit über dem UG-Auslöser von rund 20. An dem Punkt, an dem Sandy reduzieren könnte, gibt es die UG längst — also gelten dort auch wieder die vollen UG-Kosten. Die Ersparnis der Einzelunternehmens-Phase wirkt ausschließlich in der Anlaufzeit davor: früherer Break-even und ein deutlich flacherer Liquiditäts-Tiefpunkt (Abschnitte 1 und 2).
A47: Stufe | B47: Nötige Betriebe (neu) | C47: Nötiger Umsatz/Monat (neu) | D47: Nötige Betriebe (alt)
A48: Stufe B1 — 30 Std./Woche | B48: ='Plan-Phase B'!$C$22 | C48: ='Plan-Phase B'!$C$23 | D48: 37
A49: Stufe B1 — 25 Std./Woche | B49: ='Plan-Phase B'!$D$22 | C49: ='Plan-Phase B'!$D$23 | D49: 45
A50: Stufe B2 — Anstellung fällt weg | B50: ='Plan-Phase B'!$E$22 | C50: ='Plan-Phase B'!$E$23 | D50: 107
A52: Erreicht in Monat … | B52: Vorsichtig | C52: Realistisch | D52: Optimistisch
...

Sheet Plan-Annahmen
A1: Plan-Annahmen — Finanzplan CoS-F-003 (Fassung 2, 03.09.2026)
A2: Alle Eingaben des Plans an einer Stelle. Gelb = Annahme, bitte nur hier aendern. Jede Zeile nennt ihre Quelle. Horizont September 2026 bis August 2028. Rechtsform in dieser Fassung: Einzelunternehmen / Kleingewerbe, UMSATZSTEUERLICH AB 17.09.2026: Regelbesteuerung (Verzicht nach § 19 Abs. 2 UStG, Entscheidung Sandy, docs/preismodell.md) — Schalter Zeile 61 steht auf 1. UG erst ab rund 20 aktiven Betrieben.
A6: 1) Zeitrahmen
A7: Bezeichnung | B7: Wert | C7: Einheit | D7: Quelle / Kommentar
A8: Startmonat des Plans (Monat 1) | B8: 46266 | C8: Datum | D8: Horizont Sep 2026 – Aug 2028 (24 Monate), Auftrag CoS-F-003.
A9: Gate 1 — begleitete Testnutzer ab Monat | B9: 4 | C9: Monat-Nr. | D9: Nachtrag 6: Gate 1 Anfang Dezember 2026 = Monat 4. September bis November sind reine Kosten-Monate (Oktober Vorbereitung, 02.11.–03.12. Thailand, docs/kalender.md) — bewusst nicht mit Einnahmen geglättet.
A10: Öffentlicher Launch ab Monat | B10: 5 | C10: Monat-Nr. | D10: Nachtrag 6: Januar 2027 = Monat 5.
A12: 2) Preise und Stückkosten (vormals Blatt 'Marge & Tragfähigkeit')
A13: Bezeichnung | B13: Wert | C13: Einheit | D13: Quelle / Kommentar
A14: Gründerpreis | B14: 29 | C14: €/Monat | D14: docs/preismodell.md, entschieden 03.09.2026: dauerhaft für die ersten 25 zahlenden Betriebe, kein Hochlaufen auf 49 €.
A15: Standardpreis | B15: 49 | C15: €/Monat | D15: docs/preismodell.md, entschieden 03.09.2026.
A16: Gründerpreis-Plätze | B16: 25 | C16: Kunden | D16: docs/preismodell.md. Der Preisknick bei Kunde 26 ist im Kundenmodell explizit abgebildet, nicht mit einem Mischpreis geglättet (Nachtrag 3).
A17: KI-Kosten je Angebot (konservativ) | B17: 2.5 | C17: Cent | D17: Messung Head of Product Engineering (chief-of-staff-finance-todos.md, 'Rohdaten für CoS-F-002'): gemessen 2,2 Cent (Whisper $0,0060 + Chip-Vorschau $0,0002 + volle Extraktion $0,0172). Konservative Variante 2,5 Cent, weil die Aufnahmedauer nie gemessen wurde — ausdrückliche Vorgabe Chief of Staff, diesen Wert zu verwenden.
A18: Stripe-Gebühr variabel (EU-Karten) | B18: 0.015 | C18: % (Dezimal) | D18: kosten.org, Stripe-Gebührenrechner (Abruf 03.09.2026): 1,5 % + 0,25 € für europäische Karten. stripe.com/pricing lieferte beim ersten Abruf einen US-Wert (2,9 % + 30 ¢) — verworfen.
A19: Stripe-Gebühr fix je Zahlung | B19: 0.25 | C19: € | D19: Gleiche Quelle wie Zeile oben.
A20: USD/EUR-Kurs | B20: 0.86 | C20: EUR je USD | D20: exchange-rates.org: 01.09.2026 = 0,8626, 02.09.2026 = 0,8631, YTD-Ø 0,8603. Supabase, Vercel, OpenAI und Anthropic rechnen in US-Dollar — der Kurs steht deshalb sichtbar hier. Nachgeprüft 17.09.2026 (Head of Finance): Der amtliche BMF-Umsatzsteuer-Umrechnungskurs für August 2026 beträgt 1,1593 USD je EUR = 0,8626 EUR je USD und bestätigt diesen Planwert (Abweichung 0,3 %, rund 0,33 € im Monat). Bewusst zwei verschiedene Kurse mit zwei verschiedenen Aufgaben: hier ein Planungskurs für künftige Monate, im Blatt Rechnungsjournal der amtliche Monatskurs für die Buchung bereits vorliegender Belege (§ 16 Abs. 6 UStG). Bitte nicht angleichen.
A21: Angebote je Kunde und Monat | B21: 8 | C21: Angebote | D21: Stützpunkt CoS-P-008 (Platform). Liegt über dem typischen Kunden (5 Angebote) — für die Kostenseite konservativ.
A23: 3) Deckungsbeitrag je Kunde (Antwort auf CoS-F-002, hierher übernommen)
A24: Deckungsbeitrag = Preis − KI-Kosten (Angebote × Kosten je Angebot) − Stripe-Gebühr (Preis × variable Gebühr + fixe Gebühr). Der Vielnutzer-Fall mit 40 Angebten im Monat beantwortet die Frage, ob 'unbegrenzt Angebote' trägt.
A25: Angebote / Monat | B25: KI-Kosten gesamt | C25: Stripe-Gebühr | D25: Deckungsbeitrag @29€ | E25: Deckungsbeitrag @49€ | F25: Hinweis
A26: 3 | B26: =A26*$B$17/100 | C26: =$B$15*$B$18+$B$19 | D26: =$B$14-B26-($B$14*$B$18+$B$19) | E26: =$B$15-B26-C26 | F26: Leichtnutzer
A27: 5 | B27: =A27*$B$17/100 | C27: =$B$15*$B$18+$B$19 | D27: =$B$14-B27-($B$14*$B$18+$B$19) | E27: =$B$15-B27-C27 | F27: typischer Kunde
A28: 8 | B28: =A28*$B$17/100 | C28: =$B$15*$B$18+$B$19 | D28: =$B$14-B28-($B$14*$B$18+$B$19) | E28: =$B$15-B28-C28 | F28: Planannahme dieses Modells
A29: 40 | B29: =A29*$B$17/100 | C29: =$B$15*$B$18+$B$19 | D29: =$B$14-B29-($B$14*$B$18+$B$19) | E29: =$B$15-B29-C29 | F29: Vielnutzer-Fall — testet 'unbegrenzt Angebote'
A30: Ergebnis (CoS-F-002): Auch im Vielnutzer-Fall bleiben beide Deckungsbeiträge klar positiv — 40 Angebote kosten nur 1,00 € an KI. 'Unbegrenzt Angebote' ist bei diesen Preisen finanziell unkritisch. Der Plan rechnet durchgehend mit 8 Angeboten je Kunde und Monat.
A32: 4) Kundenmodell (Kanalplan CoS-M-007 + Mundpropaganda + Abwanderung)
A33: Bezeichnung | B33: Wert | C33: Einheit | D33: Quelle / Kommentar
A34: Neukunden je Kanal und Monat | B34: siehe Blatt 'Plan-Kunden' | C34: — | D34: Zulieferung Head of Marketing, docs/gtm-kanalplan.xlsx, Blatt 'Kanal x Monat' (CoS-M-007): sechs Kanäle, drei Szenarien, 24 Monate. Summen ohne Mundpropaganda und Abwanderung: 16,5 / 52,25 / 103,5 Betriebe. Werte blau auf 'Plan-Kunden' — die Bewertung des Vertriebs liegt bei Marketing, die Rechnung bei mir.
A35: Mundpropaganda: Empfehlungen pro Jahr je aktivem Betrieb — Vorsichtig | B35: 0.1 | C35: % pro Jahr | D35: gtm-kanalplan.xlsx, Blatt 'Mundpropaganda' (Parameter von Marketing, Anwendung auf die aktive Basis bei mir).
A36: Mundpropaganda: Empfehlungen pro Jahr je aktivem Betrieb — Realistisch | B36: 0.2 | C36: % pro Jahr | D36: gtm-kanalplan.xlsx, Blatt 'Mundpropaganda' (Parameter von Marketing, Anwendung auf die aktive Basis bei mir).
A37: Mundpropaganda: Empfehlungen pro Jahr je aktivem Betrieb — Optimistisch | B37: 0.35 | C37: % pro Jahr | D37: gtm-kanalplan.xlsx, Blatt 'Mundpropaganda' (Parameter von Marketing, Anwendung auf die aktive Basis bei mir).
A38: Mundpropaganda: davon zahlend — Vorsichtig | B38: 0.4 | C38: % | D38: gtm-kanalplan.xlsx, Blatt 'Mundpropaganda'.
A39: Mundpropaganda: davon zahlend — Realistisch | B39: 0.5 | C39: % | D39: gtm-kanalplan.xlsx, Blatt 'Mundpropaganda'.
A40: Mundpropaganda: davon zahlend — Optimistisch | B40: 0.6 | C40: % | D40: gtm-kanalplan.xlsx, Blatt 'Mundpropaganda'.
A41: Mundpropaganda: Verzögerung bis zur Empfehlung — Vorsichtig | B41: 4 | C41: Monate | D41: gtm-kanalplan.xlsx: ein Handwerker empfiehlt erst, wenn es sich bewährt hat. Rechenregel: aktive Betriebe (Monat − Verzögerung) × Jahresanteil ÷ 12 × Zahlend-Anteil.
A42: Mundpropaganda: Verzögerung bis zur Empfehlung — Realistisch | B42: 3 | C42: Monate | D42: gtm-kanalplan.xlsx: ein Handwerker empfiehlt erst, wenn es sich bewährt hat. Rechenregel: aktive Betriebe (Monat − Verzögerung) × Jahresanteil ÷ 12 × Zahlend-Anteil.
A43: Mundpropaganda: Verzögerung bis zur Empfehlung — Optimistisch | B43: 2 | C43: Monate | D43: gtm-kanalplan.xlsx: ein Handwerker empfiehlt erst, wenn es sich bewährt hat. Rechenregel: aktive Betriebe (Monat − Verzögerung) × Jahresanteil ÷ 12 × Zahlend-Anteil.
A44: Abwanderung Standardkunden pro Monat — Vorsichtig | B44: 0.05 | C44: % der Kunden | D44: MEINE Annahme (Abwanderung ist laut Nachtrag 3 Finance-Annahme). Marketing nennt 3–5 % im ersten Jahr als plausibel. Es gibt keinen Erfahrungswert — laut Chief of Staff bleibt diese Zelle gelb bis mindestens März 2027. Sie ist die wirksamste Stellschraube im Modell.
A45: Abwanderung Standardkunden pro Monat — Realistisch | B45: 0.04 | C45: % der Kunden | D45: MEINE Annahme (Abwanderung ist laut Nachtrag 3 Finance-Annahme). Marketing nennt 3–5 % im ersten Jahr als plausibel. Es gibt keinen Erfahrungswert — laut Chief of Staff bleibt diese Zelle gelb bis mindestens März 2027. Sie ist die wirksamste Stellschraube im Modell.
A46: Abwanderung Standardkunden pro Monat — Optimistisch | B46: 0.03 | C46: % der Kunden | D46: MEINE Annahme (Abwanderung ist laut Nachtrag 3 Finance-Annahme). Marketing nennt 3–5 % im ersten Jahr als plausibel. Es gibt keinen Erfahrungswert — laut Chief of Staff bleibt diese Zelle gelb bis mindestens März 2027. Sie ist die wirksamste Stellschraube im Modell.
...

Sheet Plan-Kunden
A1: Plan-Kunden — Kundenmodell aus Kanälen und Zeitbudget
A2: Neukunden kommen aus dem Kanalplan von Head of Marketing (blau = Zulieferung aus docs/gtm-kanalplan.xlsx, CoS-M-007), ergänzt um Mundpropaganda als einzigen Selbstverstärker aus der aktiven Kundenbasis — mit Verzögerung und dadurch von Natur aus gedeckelt. Abwanderung ist getrennt nach Gründer- und Standardkunden geführt. Rechts das Zeitbudget: Vertrieb + Support je Kunde + Onboarding je Neukunde + Grundlast gegen Sandys zwei Kapazitätslinien; eine 1 heißt, dieser Monat verlangt mehr Stunden, als sie hat. Die letzte Spalte schaltet die UG scharf, sobald die aktive Kundenzahl die Schwelle aus 'Plan-Annahmen' erreicht.
A6: Szenario: Vorsichtig | C6: Kanäle Σ 16.5 Betriebe (Marketing)
A7: Monat | B7: Kalendermonat | C7: Neukunden Kanäle | D7: Neukunden Mundpropaganda | E7: Neukunden gesamt | F7: davon Gründerplätze | G7: davon Standard | H7: Gründerplätze vergeben (kum.) | I7: Gründerkunden aktiv | J7: Standardkunden aktiv | K7: Kunden aktiv gesamt | L7: Std. Vertrieb (Marketing) | M7: Std. Support | N7: Std. Onboarding | O7: Std. Grundlast | P7: Std. gesamt | Q7: über Dauerlinie (65)? | R7: über Sprintlinie (86)? | S7: UG-Schwelle erreicht?
